[2023-10-25T15:07:16.448+0800] {taskinstance.py:1159} INFO - Dependencies all met for dep_context=non-requeueable deps ti=<TaskInstance: stock_data_crawler.get_stock_data backfill__2023-10-04T10:00:00+00:00 [queued]>
[2023-10-25T15:07:16.453+0800] {taskinstance.py:1159} INFO - Dependencies all met for dep_context=requeueable deps ti=<TaskInstance: stock_data_crawler.get_stock_data backfill__2023-10-04T10:00:00+00:00 [queued]>
[2023-10-25T15:07:16.453+0800] {taskinstance.py:1361} INFO - Starting attempt 3 of 4
[2023-10-25T15:07:16.461+0800] {taskinstance.py:1382} INFO - Executing <Task(BranchPythonOperator): get_stock_data> on 2023-10-04 10:00:00+00:00
[2023-10-25T15:07:16.467+0800] {standard_task_runner.py:57} INFO - Started process 1678 to run task
[2023-10-25T15:07:16.470+0800] {standard_task_runner.py:84} INFO - Running: ['***', 'tasks', 'run', 'stock_data_crawler', 'get_stock_data', 'backfill__2023-10-04T10:00:00+00:00', '--job-id', '286', '--pool', 'default_pool', '--raw', '--subdir', 'DAGS_FOLDER/stock_data_crawler.py', '--cfg-path', '/tmp/tmpk_bu3meg']
[2023-10-25T15:07:16.473+0800] {standard_task_runner.py:85} INFO - Job 286: Subtask get_stock_data
[2023-10-25T15:07:16.515+0800] {task_command.py:416} INFO - Running <TaskInstance: stock_data_crawler.get_stock_data backfill__2023-10-04T10:00:00+00:00 [running]> on host d9341a59eebf
[2023-10-25T15:07:16.552+0800] {taskinstance.py:1662} INFO - Exporting env vars: AIRFLOW_CTX_DAG_EMAIL='joshua881117@gmail.com' AIRFLOW_CTX_DAG_OWNER='Joshua Lin' AIRFLOW_CTX_DAG_ID='stock_data_crawler' AIRFLOW_CTX_TASK_ID='get_stock_data' AIRFLOW_CTX_EXECUTION_DATE='2023-10-04T10:00:00+00:00' AIRFLOW_CTX_TRY_NUMBER='3' AIRFLOW_CTX_DAG_RUN_ID='backfill__2023-10-04T10:00:00+00:00'
[2023-10-25T15:07:29.622+0800] {taskinstance.py:1937} ERROR - Task failed with exception
Traceback (most recent call last):
  File "/home/airflow/.local/lib/python3.8/site-packages/urllib3/connection.py", line 174, in _new_conn
    conn = connection.create_connection(
  File "/home/airflow/.local/lib/python3.8/site-packages/urllib3/util/connection.py", line 72, in create_connection
    for res in socket.getaddrinfo(host, port, family, socket.SOCK_STREAM):
  File "/usr/local/lib/python3.8/socket.py", line 918, in getaddrinfo
    for res in _socket.getaddrinfo(host, port, family, type, proto, flags):
socket.gaierror: [Errno -3] Temporary failure in name resolution

During handling of the above exception, another exception occurred:

Traceback (most recent call last):
  File "/home/airflow/.local/lib/python3.8/site-packages/urllib3/connectionpool.py", line 714, in urlopen
    httplib_response = self._make_request(
  File "/home/airflow/.local/lib/python3.8/site-packages/urllib3/connectionpool.py", line 403, in _make_request
    self._validate_conn(conn)
  File "/home/airflow/.local/lib/python3.8/site-packages/urllib3/connectionpool.py", line 1053, in _validate_conn
    conn.connect()
  File "/home/airflow/.local/lib/python3.8/site-packages/urllib3/connection.py", line 363, in connect
    self.sock = conn = self._new_conn()
  File "/home/airflow/.local/lib/python3.8/site-packages/urllib3/connection.py", line 186, in _new_conn
    raise NewConnectionError(
urllib3.exceptions.NewConnectionError: <urllib3.connection.HTTPSConnection object at 0xffff7673ac40>: Failed to establish a new connection: [Errno -3] Temporary failure in name resolution

During handling of the above exception, another exception occurred:

Traceback (most recent call last):
  File "/home/airflow/.local/lib/python3.8/site-packages/requests/adapters.py", line 486, in send
    resp = conn.urlopen(
  File "/home/airflow/.local/lib/python3.8/site-packages/urllib3/connectionpool.py", line 798, in urlopen
    retries = retries.increment(
  File "/home/airflow/.local/lib/python3.8/site-packages/urllib3/util/retry.py", line 592, in increment
    raise MaxRetryError(_pool, url, error or ResponseError(cause))
urllib3.exceptions.MaxRetryError: HTTPSConnectionPool(host='www.twse.com.tw', port=443): Max retries exceeded with url: /exchangeReport/MI_INDEX?response=json&date=20231004&type=ALL (Caused by NewConnectionError('<urllib3.connection.HTTPSConnection object at 0xffff7673ac40>: Failed to establish a new connection: [Errno -3] Temporary failure in name resolution'))

During handling of the above exception, another exception occurred:

Traceback (most recent call last):
  File "/home/airflow/.local/lib/python3.8/site-packages/airflow/operators/python.py", line 226, in execute
    branch = super().execute(context)
  File "/home/airflow/.local/lib/python3.8/site-packages/airflow/operators/python.py", line 192, in execute
    return_value = self.execute_callable()
  File "/home/airflow/.local/lib/python3.8/site-packages/airflow/operators/python.py", line 209, in execute_callable
    return self.python_callable(*self.op_args, **self.op_kwargs)
  File "/opt/airflow/dags/stock_data_crawler.py", line 43, in get_data
    df = crawler_twse(date)
  File "/opt/airflow/dags/crawler/stock_crawler.py", line 207, in crawler_twse
    res = requests.get(
  File "/home/airflow/.local/lib/python3.8/site-packages/requests/api.py", line 73, in get
    return request("get", url, params=params, **kwargs)
  File "/home/airflow/.local/lib/python3.8/site-packages/requests/api.py", line 59, in request
    return session.request(method=method, url=url, **kwargs)
  File "/home/airflow/.local/lib/python3.8/site-packages/requests/sessions.py", line 589, in request
    resp = self.send(prep, **send_kwargs)
  File "/home/airflow/.local/lib/python3.8/site-packages/requests/sessions.py", line 703, in send
    r = adapter.send(request, **kwargs)
  File "/home/airflow/.local/lib/python3.8/site-packages/requests/adapters.py", line 519, in send
    raise ConnectionError(e, request=request)
requests.exceptions.ConnectionError: HTTPSConnectionPool(host='www.twse.com.tw', port=443): Max retries exceeded with url: /exchangeReport/MI_INDEX?response=json&date=20231004&type=ALL (Caused by NewConnectionError('<urllib3.connection.HTTPSConnection object at 0xffff7673ac40>: Failed to establish a new connection: [Errno -3] Temporary failure in name resolution'))
[2023-10-25T15:07:29.689+0800] {taskinstance.py:1400} INFO - Marking task as UP_FOR_RETRY. dag_id=stock_data_crawler, task_id=get_stock_data, execution_date=20231004T100000, start_date=20231025T070716, end_date=20231025T070729
[2023-10-25T15:07:29.739+0800] {logging_mixin.py:151} WARNING - /home/***/.local/lib/python3.8/site-packages/***/utils/email.py:154 RemovedInAirflow3Warning: Fetching SMTP credentials from configuration variables will be deprecated in a future release. Please set credentials using a connection instead.
[2023-10-25T15:07:29.740+0800] {email.py:270} INFO - Email alerting: attempt 1
[2023-10-25T15:07:31.584+0800] {email.py:281} INFO - Sent an alert email to ['joshua881117@gmail.com']
[2023-10-25T15:07:33.137+0800] {standard_task_runner.py:104} ERROR - Failed to execute job 286 for task get_stock_data (HTTPSConnectionPool(host='www.twse.com.tw', port=443): Max retries exceeded with url: /exchangeReport/MI_INDEX?response=json&date=20231004&type=ALL (Caused by NewConnectionError('<urllib3.connection.HTTPSConnection object at 0xffff7673ac40>: Failed to establish a new connection: [Errno -3] Temporary failure in name resolution')); 1678)
[2023-10-25T15:07:33.199+0800] {local_task_job_runner.py:228} INFO - Task exited with return code 1
[2023-10-25T15:07:33.230+0800] {taskinstance.py:2778} INFO - 0 downstream tasks scheduled from follow-on schedule check
