[2023-10-28T02:22:25.517+0800] {taskinstance.py:1157} INFO - Dependencies all met for dep_context=non-requeueable deps ti=<TaskInstance: stock_data_crawler.get_stock_data scheduled__2023-10-26T18:00:00+00:00 [queued]>
[2023-10-28T02:22:25.522+0800] {taskinstance.py:1157} INFO - Dependencies all met for dep_context=requeueable deps ti=<TaskInstance: stock_data_crawler.get_stock_data scheduled__2023-10-26T18:00:00+00:00 [queued]>
[2023-10-28T02:22:25.522+0800] {taskinstance.py:1359} INFO - Starting attempt 1 of 2
[2023-10-28T02:22:25.529+0800] {taskinstance.py:1380} INFO - Executing <Task(BranchPythonOperator): get_stock_data> on 2023-10-26 18:00:00+00:00
[2023-10-28T02:22:25.537+0800] {standard_task_runner.py:57} INFO - Started process 11737 to run task
[2023-10-28T02:22:25.540+0800] {standard_task_runner.py:84} INFO - Running: ['***', 'tasks', 'run', 'stock_data_crawler', 'get_stock_data', 'scheduled__2023-10-26T18:00:00+00:00', '--job-id', '682', '--raw', '--subdir', 'DAGS_FOLDER/stock_data_crawler.py', '--cfg-path', '/tmp/tmpxtnf19s3']
[2023-10-28T02:22:25.545+0800] {standard_task_runner.py:85} INFO - Job 682: Subtask get_stock_data
[2023-10-28T02:22:25.578+0800] {task_command.py:415} INFO - Running <TaskInstance: stock_data_crawler.get_stock_data scheduled__2023-10-26T18:00:00+00:00 [running]> on host 9a28c8ad9082
[2023-10-28T02:22:25.616+0800] {taskinstance.py:1660} INFO - Exporting env vars: AIRFLOW_CTX_DAG_EMAIL='joshua881117@gmail.com' AIRFLOW_CTX_DAG_OWNER='Joshua Lin' AIRFLOW_CTX_DAG_ID='stock_data_crawler' AIRFLOW_CTX_TASK_ID='get_stock_data' AIRFLOW_CTX_EXECUTION_DATE='2023-10-26T18:00:00+00:00' AIRFLOW_CTX_TRY_NUMBER='1' AIRFLOW_CTX_DAG_RUN_ID='scheduled__2023-10-26T18:00:00+00:00'
[2023-10-28T02:22:25.617+0800] {logging_mixin.py:151} INFO - 2023-10-27
[2023-10-28T02:22:30.698+0800] {taskinstance.py:1935} ERROR - Task failed with exception
Traceback (most recent call last):
  File "/home/airflow/.local/lib/python3.8/site-packages/urllib3/connection.py", line 174, in _new_conn
    conn = connection.create_connection(
  File "/home/airflow/.local/lib/python3.8/site-packages/urllib3/util/connection.py", line 72, in create_connection
    for res in socket.getaddrinfo(host, port, family, socket.SOCK_STREAM):
  File "/usr/local/lib/python3.8/socket.py", line 918, in getaddrinfo
    for res in _socket.getaddrinfo(host, port, family, type, proto, flags):
socket.gaierror: [Errno -2] Name or service not known

During handling of the above exception, another exception occurred:

Traceback (most recent call last):
  File "/home/airflow/.local/lib/python3.8/site-packages/urllib3/connectionpool.py", line 714, in urlopen
    httplib_response = self._make_request(
  File "/home/airflow/.local/lib/python3.8/site-packages/urllib3/connectionpool.py", line 403, in _make_request
    self._validate_conn(conn)
  File "/home/airflow/.local/lib/python3.8/site-packages/urllib3/connectionpool.py", line 1053, in _validate_conn
    conn.connect()
  File "/home/airflow/.local/lib/python3.8/site-packages/urllib3/connection.py", line 363, in connect
    self.sock = conn = self._new_conn()
  File "/home/airflow/.local/lib/python3.8/site-packages/urllib3/connection.py", line 186, in _new_conn
    raise NewConnectionError(
urllib3.exceptions.NewConnectionError: <urllib3.connection.HTTPSConnection object at 0xffff8861a340>: Failed to establish a new connection: [Errno -2] Name or service not known

During handling of the above exception, another exception occurred:

Traceback (most recent call last):
  File "/home/airflow/.local/lib/python3.8/site-packages/requests/adapters.py", line 486, in send
    resp = conn.urlopen(
  File "/home/airflow/.local/lib/python3.8/site-packages/urllib3/connectionpool.py", line 798, in urlopen
    retries = retries.increment(
  File "/home/airflow/.local/lib/python3.8/site-packages/urllib3/util/retry.py", line 592, in increment
    raise MaxRetryError(_pool, url, error or ResponseError(cause))
urllib3.exceptions.MaxRetryError: HTTPSConnectionPool(host='www.twse.com.tw', port=443): Max retries exceeded with url: /exchangeReport/MI_INDEX?response=json&date=20231027&type=ALL (Caused by NewConnectionError('<urllib3.connection.HTTPSConnection object at 0xffff8861a340>: Failed to establish a new connection: [Errno -2] Name or service not known'))

During handling of the above exception, another exception occurred:

Traceback (most recent call last):
  File "/home/airflow/.local/lib/python3.8/site-packages/airflow/operators/python.py", line 226, in execute
    branch = super().execute(context)
  File "/home/airflow/.local/lib/python3.8/site-packages/airflow/operators/python.py", line 192, in execute
    return_value = self.execute_callable()
  File "/home/airflow/.local/lib/python3.8/site-packages/airflow/operators/python.py", line 209, in execute_callable
    return self.python_callable(*self.op_args, **self.op_kwargs)
  File "/opt/airflow/dags/stock_data_crawler.py", line 31, in get_data
    df = crawler_twse(date)
  File "/home/airflow/.local/lib/python3.8/site-packages/crawler/stock_crawler.py", line 207, in crawler_twse
    res = requests.get(
  File "/home/airflow/.local/lib/python3.8/site-packages/requests/api.py", line 73, in get
    return request("get", url, params=params, **kwargs)
  File "/home/airflow/.local/lib/python3.8/site-packages/requests/api.py", line 59, in request
    return session.request(method=method, url=url, **kwargs)
  File "/home/airflow/.local/lib/python3.8/site-packages/requests/sessions.py", line 589, in request
    resp = self.send(prep, **send_kwargs)
  File "/home/airflow/.local/lib/python3.8/site-packages/requests/sessions.py", line 703, in send
    r = adapter.send(request, **kwargs)
  File "/home/airflow/.local/lib/python3.8/site-packages/requests/adapters.py", line 519, in send
    raise ConnectionError(e, request=request)
requests.exceptions.ConnectionError: HTTPSConnectionPool(host='www.twse.com.tw', port=443): Max retries exceeded with url: /exchangeReport/MI_INDEX?response=json&date=20231027&type=ALL (Caused by NewConnectionError('<urllib3.connection.HTTPSConnection object at 0xffff8861a340>: Failed to establish a new connection: [Errno -2] Name or service not known'))
[2023-10-28T02:22:30.718+0800] {taskinstance.py:1398} INFO - Marking task as UP_FOR_RETRY. dag_id=stock_data_crawler, task_id=get_stock_data, execution_date=20231026T180000, start_date=20231027T182225, end_date=20231027T182230
[2023-10-28T02:22:30.731+0800] {standard_task_runner.py:104} ERROR - Failed to execute job 682 for task get_stock_data (HTTPSConnectionPool(host='www.twse.com.tw', port=443): Max retries exceeded with url: /exchangeReport/MI_INDEX?response=json&date=20231027&type=ALL (Caused by NewConnectionError('<urllib3.connection.HTTPSConnection object at 0xffff8861a340>: Failed to establish a new connection: [Errno -2] Name or service not known')); 11737)
[2023-10-28T02:22:30.781+0800] {local_task_job_runner.py:228} INFO - Task exited with return code 1
[2023-10-28T02:22:30.806+0800] {taskinstance.py:2776} INFO - 0 downstream tasks scheduled from follow-on schedule check
