[2023-10-25T20:32:33.558+0800] {taskinstance.py:1159} INFO - Dependencies all met for dep_context=non-requeueable deps ti=<TaskInstance: stock_data_crawler.get_stock_data scheduled__2023-10-24T10:00:00+00:00 [queued]>
[2023-10-25T20:32:33.567+0800] {taskinstance.py:1159} INFO - Dependencies all met for dep_context=requeueable deps ti=<TaskInstance: stock_data_crawler.get_stock_data scheduled__2023-10-24T10:00:00+00:00 [queued]>
[2023-10-25T20:32:33.567+0800] {taskinstance.py:1361} INFO - Starting attempt 4 of 5
[2023-10-25T20:32:33.578+0800] {taskinstance.py:1382} INFO - Executing <Task(BranchPythonOperator): get_stock_data> on 2023-10-24 10:00:00+00:00
[2023-10-25T20:32:33.590+0800] {standard_task_runner.py:57} INFO - Started process 3827 to run task
[2023-10-25T20:32:33.593+0800] {standard_task_runner.py:84} INFO - Running: ['***', 'tasks', 'run', 'stock_data_crawler', 'get_stock_data', 'scheduled__2023-10-24T10:00:00+00:00', '--job-id', '452', '--raw', '--subdir', 'DAGS_FOLDER/stock_data_crawler.py', '--cfg-path', '/tmp/tmp6vrjv6fx']
[2023-10-25T20:32:33.596+0800] {standard_task_runner.py:85} INFO - Job 452: Subtask get_stock_data
[2023-10-25T20:32:33.636+0800] {task_command.py:416} INFO - Running <TaskInstance: stock_data_crawler.get_stock_data scheduled__2023-10-24T10:00:00+00:00 [running]> on host bb5c9ebbc514
[2023-10-25T20:32:33.692+0800] {taskinstance.py:1662} INFO - Exporting env vars: AIRFLOW_CTX_DAG_EMAIL='joshua881117@gmail.com' AIRFLOW_CTX_DAG_OWNER='Joshua Lin' AIRFLOW_CTX_DAG_ID='stock_data_crawler' AIRFLOW_CTX_TASK_ID='get_stock_data' AIRFLOW_CTX_EXECUTION_DATE='2023-10-24T10:00:00+00:00' AIRFLOW_CTX_TRY_NUMBER='4' AIRFLOW_CTX_DAG_RUN_ID='scheduled__2023-10-24T10:00:00+00:00'
[2023-10-25T20:32:33.693+0800] {taskinstance.py:1937} ERROR - Task failed with exception
Traceback (most recent call last):
  File "/home/airflow/.local/lib/python3.8/site-packages/airflow/operators/python.py", line 226, in execute
    branch = super().execute(context)
  File "/home/airflow/.local/lib/python3.8/site-packages/airflow/operators/python.py", line 192, in execute
    return_value = self.execute_callable()
  File "/home/airflow/.local/lib/python3.8/site-packages/airflow/operators/python.py", line 209, in execute_callable
    return self.python_callable(*self.op_args, **self.op_kwargs)
  File "/opt/airflow/dags/stock_data_crawler.py", line 27, in get_data
    date = params.get('date', kwargs['execution_date | ds'])
KeyError: 'execution_date | ds'
[2023-10-25T20:32:33.700+0800] {taskinstance.py:1400} INFO - Marking task as UP_FOR_RETRY. dag_id=stock_data_crawler, task_id=get_stock_data, execution_date=20231024T100000, start_date=20231025T123233, end_date=20231025T123233
[2023-10-25T20:32:33.712+0800] {standard_task_runner.py:104} ERROR - Failed to execute job 452 for task get_stock_data ('execution_date | ds'; 3827)
[2023-10-25T20:32:33.725+0800] {local_task_job_runner.py:228} INFO - Task exited with return code 1
[2023-10-25T20:32:33.754+0800] {taskinstance.py:2778} INFO - 0 downstream tasks scheduled from follow-on schedule check
