[2023-10-25T16:13:25.314+0800] {taskinstance.py:1159} INFO - Dependencies all met for dep_context=non-requeueable deps ti=<TaskInstance: stock_data_crawler.get_stock_data manual__2023-10-25T16:13:13+08:00 [queued]>
[2023-10-25T16:13:25.326+0800] {taskinstance.py:1159} INFO - Dependencies all met for dep_context=requeueable deps ti=<TaskInstance: stock_data_crawler.get_stock_data manual__2023-10-25T16:13:13+08:00 [queued]>
[2023-10-25T16:13:25.327+0800] {taskinstance.py:1361} INFO - Starting attempt 1 of 2
[2023-10-25T16:13:25.343+0800] {taskinstance.py:1382} INFO - Executing <Task(BranchPythonOperator): get_stock_data> on 2023-10-25 08:13:13+00:00
[2023-10-25T16:13:25.364+0800] {standard_task_runner.py:57} INFO - Started process 6267 to run task
[2023-10-25T16:13:25.384+0800] {standard_task_runner.py:84} INFO - Running: ['***', 'tasks', 'run', 'stock_data_crawler', 'get_stock_data', 'manual__2023-10-25T16:13:13+08:00', '--job-id', '333', '--raw', '--subdir', 'DAGS_FOLDER/stock_data_crawler.py', '--cfg-path', '/tmp/tmp7ye40b25']
[2023-10-25T16:13:25.394+0800] {standard_task_runner.py:85} INFO - Job 333: Subtask get_stock_data
[2023-10-25T16:13:25.508+0800] {task_command.py:416} INFO - Running <TaskInstance: stock_data_crawler.get_stock_data manual__2023-10-25T16:13:13+08:00 [running]> on host bb5c9ebbc514
[2023-10-25T16:13:25.609+0800] {taskinstance.py:1662} INFO - Exporting env vars: AIRFLOW_CTX_DAG_EMAIL='joshua881117@gmail.com' AIRFLOW_CTX_DAG_OWNER='Joshua Lin' AIRFLOW_CTX_DAG_ID='stock_data_crawler' AIRFLOW_CTX_TASK_ID='get_stock_data' AIRFLOW_CTX_EXECUTION_DATE='2023-10-25T08:13:13+00:00' AIRFLOW_CTX_TRY_NUMBER='1' AIRFLOW_CTX_DAG_RUN_ID='manual__2023-10-25T16:13:13+08:00'
[2023-10-25T16:13:33.223+0800] {taskinstance.py:1937} ERROR - Task failed with exception
Traceback (most recent call last):
  File "/home/airflow/.local/lib/python3.8/site-packages/airflow/operators/python.py", line 226, in execute
    branch = super().execute(context)
  File "/home/airflow/.local/lib/python3.8/site-packages/airflow/operators/python.py", line 192, in execute
    return_value = self.execute_callable()
  File "/home/airflow/.local/lib/python3.8/site-packages/airflow/operators/python.py", line 209, in execute_callable
    return self.python_callable(*self.op_args, **self.op_kwargs)
  File "/opt/airflow/dags/stock_data_crawler.py", line 35, in get_data
    df.to_csv(file_path, index=False)
  File "/home/airflow/.local/lib/python3.8/site-packages/pandas/core/generic.py", line 3772, in to_csv
    return DataFrameRenderer(formatter).to_csv(
  File "/home/airflow/.local/lib/python3.8/site-packages/pandas/io/formats/format.py", line 1186, in to_csv
    csv_formatter.save()
  File "/home/airflow/.local/lib/python3.8/site-packages/pandas/io/formats/csvs.py", line 240, in save
    with get_handle(
  File "/home/airflow/.local/lib/python3.8/site-packages/pandas/io/common.py", line 737, in get_handle
    check_parent_directory(str(handle))
  File "/home/airflow/.local/lib/python3.8/site-packages/pandas/io/common.py", line 600, in check_parent_directory
    raise OSError(rf"Cannot save file into a non-existent directory: '{parent}'")
OSError: Cannot save file into a non-existent directory: '/home/***/opt/***/data'
[2023-10-25T16:13:33.255+0800] {taskinstance.py:1400} INFO - Marking task as UP_FOR_RETRY. dag_id=stock_data_crawler, task_id=get_stock_data, execution_date=20231025T081313, start_date=20231025T081325, end_date=20231025T081333
[2023-10-25T16:13:33.270+0800] {standard_task_runner.py:104} ERROR - Failed to execute job 333 for task get_stock_data (Cannot save file into a non-existent directory: '/home/***/opt/***/data'; 6267)
[2023-10-25T16:13:33.325+0800] {local_task_job_runner.py:228} INFO - Task exited with return code 1
[2023-10-25T16:13:33.363+0800] {taskinstance.py:2778} INFO - 0 downstream tasks scheduled from follow-on schedule check
