[2023-10-19T12:07:38.139+0000] {taskinstance.py:1159} INFO - Dependencies all met for dep_context=non-requeueable deps ti=<TaskInstance: stock_notification.get_stock_data manual__2023-10-19T12:07:34.769184+00:00 [queued]>
[2023-10-19T12:07:38.144+0000] {taskinstance.py:1159} INFO - Dependencies all met for dep_context=requeueable deps ti=<TaskInstance: stock_notification.get_stock_data manual__2023-10-19T12:07:34.769184+00:00 [queued]>
[2023-10-19T12:07:38.144+0000] {taskinstance.py:1361} INFO - Starting attempt 1 of 3
[2023-10-19T12:07:38.154+0000] {taskinstance.py:1382} INFO - Executing <Task(PythonOperator): get_stock_data> on 2023-10-19 12:07:34.769184+00:00
[2023-10-19T12:07:38.197+0000] {standard_task_runner.py:57} INFO - Started process 1813 to run task
[2023-10-19T12:07:38.209+0000] {standard_task_runner.py:84} INFO - Running: ['***', 'tasks', 'run', 'stock_notification', 'get_stock_data', 'manual__2023-10-19T12:07:34.769184+00:00', '--job-id', '26', '--raw', '--subdir', 'DAGS_FOLDER/stock_notification.py', '--cfg-path', '/tmp/tmpridn42ne']
[2023-10-19T12:07:38.216+0000] {standard_task_runner.py:85} INFO - Job 26: Subtask get_stock_data
[2023-10-19T12:07:38.247+0000] {task_command.py:416} INFO - Running <TaskInstance: stock_notification.get_stock_data manual__2023-10-19T12:07:34.769184+00:00 [running]> on host 46830eaaaf4f
[2023-10-19T12:07:38.585+0000] {taskinstance.py:1662} INFO - Exporting env vars: AIRFLOW_CTX_DAG_EMAIL='joshua881117@gmail.com' AIRFLOW_CTX_DAG_OWNER='Joshua Lin' AIRFLOW_CTX_DAG_ID='stock_notification' AIRFLOW_CTX_TASK_ID='get_stock_data' AIRFLOW_CTX_EXECUTION_DATE='2023-10-19T12:07:34.769184+00:00' AIRFLOW_CTX_TRY_NUMBER='1' AIRFLOW_CTX_DAG_RUN_ID='manual__2023-10-19T12:07:34.769184+00:00'
[2023-10-19T12:07:38.586+0000] {log.py:232} WARNING - 2023-10-19 12:07:38.586 | INFO     | stock_app.stock_crawler:crawler_twse:198 - crawler_twse
[2023-10-19T12:07:45.853+0000] {log.py:232} WARNING - 2023-10-19 12:07:45.852 | INFO     | stock_app.stock_crawler:convert_change:254 - convert_change
[2023-10-19T12:07:46.236+0000] {logging_mixin.py:151} INFO - /opt/***/dags
[2023-10-19T12:07:46.237+0000] {logging_mixin.py:151} INFO - /opt/***/dags/data/stock_data.csv
[2023-10-19T12:07:46.321+0000] {python.py:194} INFO - Done. Returned value was:       StockID TradeVolume Transaction  ...   Close Change        Date
0        0050     8052218        5999  ...  124.85   0.05  2023-10-19
1        0051       60693         218  ...   68.60    0.0  2023-10-19
2        0052      420994         451  ...  116.45    0.9  2023-10-19
3        0053        6822          25  ...   67.20  -0.05  2023-10-19
4        0055       72949         173  ...   23.51  -0.11  2023-10-19
...       ...         ...         ...  ...     ...    ...         ...
30308    9944       66113          63  ...   19.60    0.0  2023-10-19
30309    9945     5503434        4504  ...   33.40   -0.7  2023-10-19
30310    9946      725740         335  ...   17.30  -0.05  2023-10-19
30311    9955     7567815        4615  ...   26.50   0.35  2023-10-19
30312    9958     2845216        1829  ...  173.00   -2.0  2023-10-19

[30313 rows x 10 columns]
[2023-10-19T12:07:46.662+0000] {taskinstance.py:1937} ERROR - Task failed with exception
Traceback (most recent call last):
  File "/home/airflow/.local/lib/python3.8/site-packages/sqlalchemy/engine/base.py", line 1910, in _execute_context
    self.dialect.do_execute(
  File "/home/airflow/.local/lib/python3.8/site-packages/sqlalchemy/engine/default.py", line 736, in do_execute
    cursor.execute(statement, parameters)
  File "/home/airflow/.local/lib/python3.8/site-packages/pymysql/cursors.py", line 153, in execute
    result = self._query(query)
  File "/home/airflow/.local/lib/python3.8/site-packages/pymysql/cursors.py", line 322, in _query
    conn.query(q)
  File "/home/airflow/.local/lib/python3.8/site-packages/pymysql/connections.py", line 558, in query
    self._affected_rows = self._read_query_result(unbuffered=unbuffered)
  File "/home/airflow/.local/lib/python3.8/site-packages/pymysql/connections.py", line 822, in _read_query_result
    result.read()
  File "/home/airflow/.local/lib/python3.8/site-packages/pymysql/connections.py", line 1200, in read
    first_packet = self.connection._read_packet()
  File "/home/airflow/.local/lib/python3.8/site-packages/pymysql/connections.py", line 772, in _read_packet
    packet.raise_for_error()
  File "/home/airflow/.local/lib/python3.8/site-packages/pymysql/protocol.py", line 221, in raise_for_error
    err.raise_mysql_exception(self._data)
  File "/home/airflow/.local/lib/python3.8/site-packages/pymysql/err.py", line 143, in raise_mysql_exception
    raise errorclass(errno, errval)
pymysql.err.DataError: (1406, "Data too long for column 'value' at row 1")

The above exception was the direct cause of the following exception:

Traceback (most recent call last):
  File "/home/airflow/.local/lib/python3.8/site-packages/airflow/utils/session.py", line 74, in wrapper
    return func(*args, **kwargs)
  File "/home/airflow/.local/lib/python3.8/site-packages/airflow/models/taskinstance.py", line 2479, in xcom_push
    XCom.set(
  File "/home/airflow/.local/lib/python3.8/site-packages/airflow/utils/session.py", line 74, in wrapper
    return func(*args, **kwargs)
  File "/home/airflow/.local/lib/python3.8/site-packages/airflow/models/xcom.py", line 273, in set
    session.flush()
  File "/home/airflow/.local/lib/python3.8/site-packages/sqlalchemy/orm/session.py", line 3449, in flush
    self._flush(objects)
  File "/home/airflow/.local/lib/python3.8/site-packages/sqlalchemy/orm/session.py", line 3589, in _flush
    transaction.rollback(_capture_exception=True)
  File "/home/airflow/.local/lib/python3.8/site-packages/sqlalchemy/util/langhelpers.py", line 70, in __exit__
    compat.raise_(
  File "/home/airflow/.local/lib/python3.8/site-packages/sqlalchemy/util/compat.py", line 211, in raise_
    raise exception
  File "/home/airflow/.local/lib/python3.8/site-packages/sqlalchemy/orm/session.py", line 3549, in _flush
    flush_context.execute()
  File "/home/airflow/.local/lib/python3.8/site-packages/sqlalchemy/orm/unitofwork.py", line 456, in execute
    rec.execute(self)
  File "/home/airflow/.local/lib/python3.8/site-packages/sqlalchemy/orm/unitofwork.py", line 630, in execute
    util.preloaded.orm_persistence.save_obj(
  File "/home/airflow/.local/lib/python3.8/site-packages/sqlalchemy/orm/persistence.py", line 245, in save_obj
    _emit_insert_statements(
  File "/home/airflow/.local/lib/python3.8/site-packages/sqlalchemy/orm/persistence.py", line 1097, in _emit_insert_statements
    c = connection._execute_20(
  File "/home/airflow/.local/lib/python3.8/site-packages/sqlalchemy/engine/base.py", line 1710, in _execute_20
    return meth(self, args_10style, kwargs_10style, execution_options)
  File "/home/airflow/.local/lib/python3.8/site-packages/sqlalchemy/sql/elements.py", line 334, in _execute_on_connection
    return connection._execute_clauseelement(
  File "/home/airflow/.local/lib/python3.8/site-packages/sqlalchemy/engine/base.py", line 1577, in _execute_clauseelement
    ret = self._execute_context(
  File "/home/airflow/.local/lib/python3.8/site-packages/sqlalchemy/engine/base.py", line 1953, in _execute_context
    self._handle_dbapi_exception(
  File "/home/airflow/.local/lib/python3.8/site-packages/sqlalchemy/engine/base.py", line 2134, in _handle_dbapi_exception
    util.raise_(
  File "/home/airflow/.local/lib/python3.8/site-packages/sqlalchemy/util/compat.py", line 211, in raise_
    raise exception
  File "/home/airflow/.local/lib/python3.8/site-packages/sqlalchemy/engine/base.py", line 1910, in _execute_context
    self.dialect.do_execute(
  File "/home/airflow/.local/lib/python3.8/site-packages/sqlalchemy/engine/default.py", line 736, in do_execute
    cursor.execute(statement, parameters)
  File "/home/airflow/.local/lib/python3.8/site-packages/pymysql/cursors.py", line 153, in execute
    result = self._query(query)
  File "/home/airflow/.local/lib/python3.8/site-packages/pymysql/cursors.py", line 322, in _query
    conn.query(q)
  File "/home/airflow/.local/lib/python3.8/site-packages/pymysql/connections.py", line 558, in query
    self._affected_rows = self._read_query_result(unbuffered=unbuffered)
  File "/home/airflow/.local/lib/python3.8/site-packages/pymysql/connections.py", line 822, in _read_query_result
    result.read()
  File "/home/airflow/.local/lib/python3.8/site-packages/pymysql/connections.py", line 1200, in read
    first_packet = self.connection._read_packet()
  File "/home/airflow/.local/lib/python3.8/site-packages/pymysql/connections.py", line 772, in _read_packet
    packet.raise_for_error()
  File "/home/airflow/.local/lib/python3.8/site-packages/pymysql/protocol.py", line 221, in raise_for_error
    err.raise_mysql_exception(self._data)
  File "/home/airflow/.local/lib/python3.8/site-packages/pymysql/err.py", line 143, in raise_mysql_exception
    raise errorclass(errno, errval)
sqlalchemy.exc.DataError: (pymysql.err.DataError) (1406, "Data too long for column 'value' at row 1")
[SQL: INSERT INTO xcom (dag_run_id, task_id, map_index, `key`, dag_id, run_id, value, timestamp) VALUES (%(dag_run_id)s, %(task_id)s, %(map_index)s, %(key)s, %(dag_id)s, %(run_id)s, %(value)s, %(timestamp)s)]
[parameters: {'dag_run_id': 12, 'task_id': 'get_stock_data', 'map_index': -1, 'key': 'return_value', 'dag_id': 'stock_notification', 'run_id': 'manual__2023-10-19T12:07:34.769184+00:00', 'value': b'{"__classname__": "pandas.core.frame.DataFrame", "__version__": 1, "__data__": "50415231150415D0DF2415BEA4104C15D2D9031500120000E8AF121C040000003030 ... (1091433 characters truncated) ... 0706172717565742D6370702D6172726F772076657273696F6E2031312E302E3019AC1C00001C00001C00001C00001C00001C00001C00001C00001C00001C0000009814000050415231"}', 'timestamp': datetime.datetime(2023, 10, 19, 12, 7, 46, 620535)}]
(Background on this error at: https://sqlalche.me/e/14/9h9h)
[2023-10-19T12:07:46.690+0000] {taskinstance.py:1400} INFO - Marking task as UP_FOR_RETRY. dag_id=stock_notification, task_id=get_stock_data, execution_date=20231019T120734, start_date=20231019T120738, end_date=20231019T120746
[2023-10-19T12:07:46.726+0000] {warnings.py:109} WARNING - /home/***/.local/lib/python3.8/site-packages/***/utils/email.py:154: RemovedInAirflow3Warning: Fetching SMTP credentials from configuration variables will be deprecated in a future release. Please set credentials using a connection instead.
  send_mime_email(e_from=mail_from, e_to=recipients, mime_msg=msg, conn_id=conn_id, dryrun=dryrun)

[2023-10-19T12:07:46.727+0000] {configuration.py:1068} WARNING - section/key [smtp/smtp_user] not found in config
[2023-10-19T12:07:46.727+0000] {email.py:270} INFO - Email alerting: attempt 1
[2023-10-19T12:07:46.732+0000] {configuration.py:1068} WARNING - section/key [smtp/smtp_user] not found in config
[2023-10-19T12:07:46.732+0000] {email.py:270} INFO - Email alerting: attempt 1
[2023-10-19T12:07:46.732+0000] {taskinstance.py:2007} ERROR - Failed to send email to: ['joshua881117@gmail.com']
Traceback (most recent call last):
  File "/home/airflow/.local/lib/python3.8/site-packages/sqlalchemy/engine/base.py", line 1910, in _execute_context
    self.dialect.do_execute(
  File "/home/airflow/.local/lib/python3.8/site-packages/sqlalchemy/engine/default.py", line 736, in do_execute
    cursor.execute(statement, parameters)
  File "/home/airflow/.local/lib/python3.8/site-packages/pymysql/cursors.py", line 153, in execute
    result = self._query(query)
  File "/home/airflow/.local/lib/python3.8/site-packages/pymysql/cursors.py", line 322, in _query
    conn.query(q)
  File "/home/airflow/.local/lib/python3.8/site-packages/pymysql/connections.py", line 558, in query
    self._affected_rows = self._read_query_result(unbuffered=unbuffered)
  File "/home/airflow/.local/lib/python3.8/site-packages/pymysql/connections.py", line 822, in _read_query_result
    result.read()
  File "/home/airflow/.local/lib/python3.8/site-packages/pymysql/connections.py", line 1200, in read
    first_packet = self.connection._read_packet()
  File "/home/airflow/.local/lib/python3.8/site-packages/pymysql/connections.py", line 772, in _read_packet
    packet.raise_for_error()
  File "/home/airflow/.local/lib/python3.8/site-packages/pymysql/protocol.py", line 221, in raise_for_error
    err.raise_mysql_exception(self._data)
  File "/home/airflow/.local/lib/python3.8/site-packages/pymysql/err.py", line 143, in raise_mysql_exception
    raise errorclass(errno, errval)
pymysql.err.DataError: (1406, "Data too long for column 'value' at row 1")

The above exception was the direct cause of the following exception:

Traceback (most recent call last):
  File "/home/airflow/.local/lib/python3.8/site-packages/airflow/models/taskinstance.py", line 1518, in _run_raw_task
    self._execute_task_with_callbacks(context, test_mode, session=session)
  File "/home/airflow/.local/lib/python3.8/site-packages/airflow/models/taskinstance.py", line 1681, in _execute_task_with_callbacks
    result = self._execute_task(context, task_orig)
  File "/home/airflow/.local/lib/python3.8/site-packages/airflow/models/taskinstance.py", line 1751, in _execute_task
    self.xcom_push(key=XCOM_RETURN_KEY, value=xcom_value, session=session)
  File "/home/airflow/.local/lib/python3.8/site-packages/airflow/utils/session.py", line 74, in wrapper
    return func(*args, **kwargs)
  File "/home/airflow/.local/lib/python3.8/site-packages/airflow/models/taskinstance.py", line 2479, in xcom_push
    XCom.set(
  File "/home/airflow/.local/lib/python3.8/site-packages/airflow/utils/session.py", line 74, in wrapper
    return func(*args, **kwargs)
  File "/home/airflow/.local/lib/python3.8/site-packages/airflow/models/xcom.py", line 273, in set
    session.flush()
  File "/home/airflow/.local/lib/python3.8/site-packages/sqlalchemy/orm/session.py", line 3449, in flush
    self._flush(objects)
  File "/home/airflow/.local/lib/python3.8/site-packages/sqlalchemy/orm/session.py", line 3589, in _flush
    transaction.rollback(_capture_exception=True)
  File "/home/airflow/.local/lib/python3.8/site-packages/sqlalchemy/util/langhelpers.py", line 70, in __exit__
    compat.raise_(
  File "/home/airflow/.local/lib/python3.8/site-packages/sqlalchemy/util/compat.py", line 211, in raise_
    raise exception
  File "/home/airflow/.local/lib/python3.8/site-packages/sqlalchemy/orm/session.py", line 3549, in _flush
    flush_context.execute()
  File "/home/airflow/.local/lib/python3.8/site-packages/sqlalchemy/orm/unitofwork.py", line 456, in execute
    rec.execute(self)
  File "/home/airflow/.local/lib/python3.8/site-packages/sqlalchemy/orm/unitofwork.py", line 630, in execute
    util.preloaded.orm_persistence.save_obj(
  File "/home/airflow/.local/lib/python3.8/site-packages/sqlalchemy/orm/persistence.py", line 245, in save_obj
    _emit_insert_statements(
  File "/home/airflow/.local/lib/python3.8/site-packages/sqlalchemy/orm/persistence.py", line 1097, in _emit_insert_statements
    c = connection._execute_20(
  File "/home/airflow/.local/lib/python3.8/site-packages/sqlalchemy/engine/base.py", line 1710, in _execute_20
    return meth(self, args_10style, kwargs_10style, execution_options)
  File "/home/airflow/.local/lib/python3.8/site-packages/sqlalchemy/sql/elements.py", line 334, in _execute_on_connection
    return connection._execute_clauseelement(
  File "/home/airflow/.local/lib/python3.8/site-packages/sqlalchemy/engine/base.py", line 1577, in _execute_clauseelement
    ret = self._execute_context(
  File "/home/airflow/.local/lib/python3.8/site-packages/sqlalchemy/engine/base.py", line 1953, in _execute_context
    self._handle_dbapi_exception(
  File "/home/airflow/.local/lib/python3.8/site-packages/sqlalchemy/engine/base.py", line 2134, in _handle_dbapi_exception
    util.raise_(
  File "/home/airflow/.local/lib/python3.8/site-packages/sqlalchemy/util/compat.py", line 211, in raise_
    raise exception
  File "/home/airflow/.local/lib/python3.8/site-packages/sqlalchemy/engine/base.py", line 1910, in _execute_context
    self.dialect.do_execute(
  File "/home/airflow/.local/lib/python3.8/site-packages/sqlalchemy/engine/default.py", line 736, in do_execute
    cursor.execute(statement, parameters)
  File "/home/airflow/.local/lib/python3.8/site-packages/pymysql/cursors.py", line 153, in execute
    result = self._query(query)
  File "/home/airflow/.local/lib/python3.8/site-packages/pymysql/cursors.py", line 322, in _query
    conn.query(q)
  File "/home/airflow/.local/lib/python3.8/site-packages/pymysql/connections.py", line 558, in query
    self._affected_rows = self._read_query_result(unbuffered=unbuffered)
  File "/home/airflow/.local/lib/python3.8/site-packages/pymysql/connections.py", line 822, in _read_query_result
    result.read()
  File "/home/airflow/.local/lib/python3.8/site-packages/pymysql/connections.py", line 1200, in read
    first_packet = self.connection._read_packet()
  File "/home/airflow/.local/lib/python3.8/site-packages/pymysql/connections.py", line 772, in _read_packet
    packet.raise_for_error()
  File "/home/airflow/.local/lib/python3.8/site-packages/pymysql/protocol.py", line 221, in raise_for_error
    err.raise_mysql_exception(self._data)
  File "/home/airflow/.local/lib/python3.8/site-packages/pymysql/err.py", line 143, in raise_mysql_exception
    raise errorclass(errno, errval)
sqlalchemy.exc.DataError: (pymysql.err.DataError) (1406, "Data too long for column 'value' at row 1")
[SQL: INSERT INTO xcom (dag_run_id, task_id, map_index, `key`, dag_id, run_id, value, timestamp) VALUES (%(dag_run_id)s, %(task_id)s, %(map_index)s, %(key)s, %(dag_id)s, %(run_id)s, %(value)s, %(timestamp)s)]
[parameters: {'dag_run_id': 12, 'task_id': 'get_stock_data', 'map_index': -1, 'key': 'return_value', 'dag_id': 'stock_notification', 'run_id': 'manual__2023-10-19T12:07:34.769184+00:00', 'value': b'{"__classname__": "pandas.core.frame.DataFrame", "__version__": 1, "__data__": "50415231150415D0DF2415BEA4104C15D2D9031500120000E8AF121C040000003030 ... (1091433 characters truncated) ... 0706172717565742D6370702D6172726F772076657273696F6E2031312E302E3019AC1C00001C00001C00001C00001C00001C00001C00001C00001C00001C0000009814000050415231"}', 'timestamp': datetime.datetime(2023, 10, 19, 12, 7, 46, 620535)}]
(Background on this error at: https://sqlalche.me/e/14/9h9h)

During handling of the above exception, another exception occurred:

Traceback (most recent call last):
  File "/home/airflow/.local/lib/python3.8/site-packages/airflow/models/taskinstance.py", line 2420, in email_alert
    send_email(task.email, subject, html_content)
  File "/home/airflow/.local/lib/python3.8/site-packages/airflow/utils/email.py", line 80, in send_email
    return backend(
  File "/home/airflow/.local/lib/python3.8/site-packages/airflow/utils/email.py", line 154, in send_email_smtp
    send_mime_email(e_from=mail_from, e_to=recipients, mime_msg=msg, conn_id=conn_id, dryrun=dryrun)
  File "/home/airflow/.local/lib/python3.8/site-packages/airflow/utils/email.py", line 272, in send_mime_email
    smtp_conn = _get_smtp_connection(smtp_host, smtp_port, smtp_timeout, smtp_ssl)
  File "/home/airflow/.local/lib/python3.8/site-packages/airflow/utils/email.py", line 316, in _get_smtp_connection
    return smtplib.SMTP(host=host, port=port, timeout=timeout)
  File "/usr/local/lib/python3.8/smtplib.py", line 255, in __init__
    (code, msg) = self.connect(host, port)
  File "/usr/local/lib/python3.8/smtplib.py", line 339, in connect
    self.sock = self._get_socket(host, port, self.timeout)
  File "/usr/local/lib/python3.8/smtplib.py", line 310, in _get_socket
    return socket.create_connection((host, port), timeout,
  File "/usr/local/lib/python3.8/socket.py", line 808, in create_connection
    raise err
  File "/usr/local/lib/python3.8/socket.py", line 796, in create_connection
    sock.connect(sa)
OSError: [Errno 99] Cannot assign requested address

During handling of the above exception, another exception occurred:

Traceback (most recent call last):
  File "/home/airflow/.local/lib/python3.8/site-packages/airflow/models/taskinstance.py", line 2005, in handle_failure
    self.email_alert(error, task)
  File "/home/airflow/.local/lib/python3.8/site-packages/airflow/models/taskinstance.py", line 2422, in email_alert
    send_email(task.email, subject, html_content_err)
  File "/home/airflow/.local/lib/python3.8/site-packages/airflow/utils/email.py", line 80, in send_email
    return backend(
  File "/home/airflow/.local/lib/python3.8/site-packages/airflow/utils/email.py", line 154, in send_email_smtp
    send_mime_email(e_from=mail_from, e_to=recipients, mime_msg=msg, conn_id=conn_id, dryrun=dryrun)
  File "/home/airflow/.local/lib/python3.8/site-packages/airflow/utils/email.py", line 272, in send_mime_email
    smtp_conn = _get_smtp_connection(smtp_host, smtp_port, smtp_timeout, smtp_ssl)
  File "/home/airflow/.local/lib/python3.8/site-packages/airflow/utils/email.py", line 316, in _get_smtp_connection
    return smtplib.SMTP(host=host, port=port, timeout=timeout)
  File "/usr/local/lib/python3.8/smtplib.py", line 255, in __init__
    (code, msg) = self.connect(host, port)
  File "/usr/local/lib/python3.8/smtplib.py", line 339, in connect
    self.sock = self._get_socket(host, port, self.timeout)
  File "/usr/local/lib/python3.8/smtplib.py", line 310, in _get_socket
    return socket.create_connection((host, port), timeout,
  File "/usr/local/lib/python3.8/socket.py", line 808, in create_connection
    raise err
  File "/usr/local/lib/python3.8/socket.py", line 796, in create_connection
    sock.connect(sa)
OSError: [Errno 99] Cannot assign requested address
[2023-10-19T12:07:46.751+0000] {standard_task_runner.py:104} ERROR - Failed to execute job 26 for task get_stock_data ((pymysql.err.DataError) (1406, "Data too long for column 'value' at row 1")
[SQL: INSERT INTO xcom (dag_run_id, task_id, map_index, `key`, dag_id, run_id, value, timestamp) VALUES (%(dag_run_id)s, %(task_id)s, %(map_index)s, %(key)s, %(dag_id)s, %(run_id)s, %(value)s, %(timestamp)s)]
[parameters: {'dag_run_id': 12, 'task_id': 'get_stock_data', 'map_index': -1, 'key': 'return_value', 'dag_id': 'stock_notification', 'run_id': 'manual__2023-10-19T12:07:34.769184+00:00', 'value': b'{"__classname__": "pandas.core.frame.DataFrame", "__version__": 1, "__data__": "50415231150415D0DF2415BEA4104C15D2D9031500120000E8AF121C040000003030 ... (1091433 characters truncated) ... 0706172717565742D6370702D6172726F772076657273696F6E2031312E302E3019AC1C00001C00001C00001C00001C00001C00001C00001C00001C00001C0000009814000050415231"}', 'timestamp': datetime.datetime(2023, 10, 19, 12, 7, 46, 620535)}]
(Background on this error at: https://sqlalche.me/e/14/9h9h); 1813)
[2023-10-19T12:07:46.838+0000] {local_task_job_runner.py:228} INFO - Task exited with return code 1
[2023-10-19T12:07:47.227+0000] {taskinstance.py:2778} INFO - 0 downstream tasks scheduled from follow-on schedule check
