[2023-10-21T16:46:29.163+0800] {taskinstance.py:1159} INFO - Dependencies all met for dep_context=non-requeueable deps ti=<TaskInstance: stock_notification.check_stock_price manual__2023-10-21T08:46:13.246640+00:00 [queued]>
[2023-10-21T16:46:29.173+0800] {taskinstance.py:1159} INFO - Dependencies all met for dep_context=requeueable deps ti=<TaskInstance: stock_notification.check_stock_price manual__2023-10-21T08:46:13.246640+00:00 [queued]>
[2023-10-21T16:46:29.173+0800] {taskinstance.py:1361} INFO - Starting attempt 1 of 3
[2023-10-21T16:46:29.181+0800] {taskinstance.py:1382} INFO - Executing <Task(PythonOperator): check_stock_price> on 2023-10-21 08:46:13.246640+00:00
[2023-10-21T16:46:29.191+0800] {standard_task_runner.py:57} INFO - Started process 254 to run task
[2023-10-21T16:46:29.196+0800] {standard_task_runner.py:84} INFO - Running: ['***', 'tasks', 'run', 'stock_notification', 'check_stock_price', 'manual__2023-10-21T08:46:13.246640+00:00', '--job-id', '199', '--raw', '--subdir', 'DAGS_FOLDER/stock_notification.py', '--cfg-path', '/tmp/tmprvoaodbf']
[2023-10-21T16:46:29.199+0800] {standard_task_runner.py:85} INFO - Job 199: Subtask check_stock_price
[2023-10-21T16:46:29.222+0800] {task_command.py:416} INFO - Running <TaskInstance: stock_notification.check_stock_price manual__2023-10-21T08:46:13.246640+00:00 [running]> on host 6a6999315df3
[2023-10-21T16:46:29.266+0800] {taskinstance.py:1662} INFO - Exporting env vars: AIRFLOW_CTX_DAG_EMAIL='joshua881117@gmail.com' AIRFLOW_CTX_DAG_OWNER='Joshua Lin' AIRFLOW_CTX_DAG_ID='stock_notification' AIRFLOW_CTX_TASK_ID='check_stock_price' AIRFLOW_CTX_EXECUTION_DATE='2023-10-21T08:46:13.246640+00:00' AIRFLOW_CTX_TRY_NUMBER='1' AIRFLOW_CTX_DAG_RUN_ID='manual__2023-10-21T08:46:13.246640+00:00'
[2023-10-21T16:46:29.267+0800] {taskinstance.py:1937} ERROR - Task failed with exception
Traceback (most recent call last):
  File "/home/airflow/.local/lib/python3.8/site-packages/airflow/operators/python.py", line 192, in execute
    return_value = self.execute_callable()
  File "/home/airflow/.local/lib/python3.8/site-packages/airflow/operators/python.py", line 209, in execute_callable
    return self.python_callable(*self.op_args, **self.op_kwargs)
  File "/opt/airflow/dags/stock_notification.py", line 46, in check_price
    target_df = context['task_instance'].xcom_pull(task_id='get_target')
  File "/home/airflow/.local/lib/python3.8/site-packages/airflow/utils/session.py", line 77, in wrapper
    return func(*args, session=session, **kwargs)
TypeError: xcom_pull() got an unexpected keyword argument 'task_id'
[2023-10-21T16:46:29.273+0800] {taskinstance.py:1400} INFO - Marking task as UP_FOR_RETRY. dag_id=stock_notification, task_id=check_stock_price, execution_date=20231021T084613, start_date=20231021T084629, end_date=20231021T084629
[2023-10-21T16:46:29.281+0800] {warnings.py:109} WARNING - /home/***/.local/lib/python3.8/site-packages/***/utils/email.py:154: RemovedInAirflow3Warning: Fetching SMTP credentials from configuration variables will be deprecated in a future release. Please set credentials using a connection instead.
  send_mime_email(e_from=mail_from, e_to=recipients, mime_msg=msg, conn_id=conn_id, dryrun=dryrun)

[2023-10-21T16:46:29.281+0800] {configuration.py:1068} WARNING - section/key [smtp/smtp_user] not found in config
[2023-10-21T16:46:29.281+0800] {email.py:270} INFO - Email alerting: attempt 1
[2023-10-21T16:46:29.284+0800] {configuration.py:1068} WARNING - section/key [smtp/smtp_user] not found in config
[2023-10-21T16:46:29.284+0800] {email.py:270} INFO - Email alerting: attempt 1
[2023-10-21T16:46:29.284+0800] {taskinstance.py:2007} ERROR - Failed to send email to: ['joshua881117@gmail.com']
Traceback (most recent call last):
  File "/home/airflow/.local/lib/python3.8/site-packages/airflow/models/taskinstance.py", line 1518, in _run_raw_task
    self._execute_task_with_callbacks(context, test_mode, session=session)
  File "/home/airflow/.local/lib/python3.8/site-packages/airflow/models/taskinstance.py", line 1681, in _execute_task_with_callbacks
    result = self._execute_task(context, task_orig)
  File "/home/airflow/.local/lib/python3.8/site-packages/airflow/models/taskinstance.py", line 1744, in _execute_task
    result = execute_callable(context=context, **execute_callable_kwargs)
  File "/home/airflow/.local/lib/python3.8/site-packages/airflow/operators/python.py", line 192, in execute
    return_value = self.execute_callable()
  File "/home/airflow/.local/lib/python3.8/site-packages/airflow/operators/python.py", line 209, in execute_callable
    return self.python_callable(*self.op_args, **self.op_kwargs)
  File "/opt/airflow/dags/stock_notification.py", line 46, in check_price
    target_df = context['task_instance'].xcom_pull(task_id='get_target')
  File "/home/airflow/.local/lib/python3.8/site-packages/airflow/utils/session.py", line 77, in wrapper
    return func(*args, session=session, **kwargs)
TypeError: xcom_pull() got an unexpected keyword argument 'task_id'

During handling of the above exception, another exception occurred:

Traceback (most recent call last):
  File "/home/airflow/.local/lib/python3.8/site-packages/airflow/models/taskinstance.py", line 2420, in email_alert
    send_email(task.email, subject, html_content)
  File "/home/airflow/.local/lib/python3.8/site-packages/airflow/utils/email.py", line 80, in send_email
    return backend(
  File "/home/airflow/.local/lib/python3.8/site-packages/airflow/utils/email.py", line 154, in send_email_smtp
    send_mime_email(e_from=mail_from, e_to=recipients, mime_msg=msg, conn_id=conn_id, dryrun=dryrun)
  File "/home/airflow/.local/lib/python3.8/site-packages/airflow/utils/email.py", line 272, in send_mime_email
    smtp_conn = _get_smtp_connection(smtp_host, smtp_port, smtp_timeout, smtp_ssl)
  File "/home/airflow/.local/lib/python3.8/site-packages/airflow/utils/email.py", line 316, in _get_smtp_connection
    return smtplib.SMTP(host=host, port=port, timeout=timeout)
  File "/usr/local/lib/python3.8/smtplib.py", line 255, in __init__
    (code, msg) = self.connect(host, port)
  File "/usr/local/lib/python3.8/smtplib.py", line 339, in connect
    self.sock = self._get_socket(host, port, self.timeout)
  File "/usr/local/lib/python3.8/smtplib.py", line 310, in _get_socket
    return socket.create_connection((host, port), timeout,
  File "/usr/local/lib/python3.8/socket.py", line 808, in create_connection
    raise err
  File "/usr/local/lib/python3.8/socket.py", line 796, in create_connection
    sock.connect(sa)
OSError: [Errno 99] Cannot assign requested address

During handling of the above exception, another exception occurred:

Traceback (most recent call last):
  File "/home/airflow/.local/lib/python3.8/site-packages/airflow/models/taskinstance.py", line 2005, in handle_failure
    self.email_alert(error, task)
  File "/home/airflow/.local/lib/python3.8/site-packages/airflow/models/taskinstance.py", line 2422, in email_alert
    send_email(task.email, subject, html_content_err)
  File "/home/airflow/.local/lib/python3.8/site-packages/airflow/utils/email.py", line 80, in send_email
    return backend(
  File "/home/airflow/.local/lib/python3.8/site-packages/airflow/utils/email.py", line 154, in send_email_smtp
    send_mime_email(e_from=mail_from, e_to=recipients, mime_msg=msg, conn_id=conn_id, dryrun=dryrun)
  File "/home/airflow/.local/lib/python3.8/site-packages/airflow/utils/email.py", line 272, in send_mime_email
    smtp_conn = _get_smtp_connection(smtp_host, smtp_port, smtp_timeout, smtp_ssl)
  File "/home/airflow/.local/lib/python3.8/site-packages/airflow/utils/email.py", line 316, in _get_smtp_connection
    return smtplib.SMTP(host=host, port=port, timeout=timeout)
  File "/usr/local/lib/python3.8/smtplib.py", line 255, in __init__
    (code, msg) = self.connect(host, port)
  File "/usr/local/lib/python3.8/smtplib.py", line 339, in connect
    self.sock = self._get_socket(host, port, self.timeout)
  File "/usr/local/lib/python3.8/smtplib.py", line 310, in _get_socket
    return socket.create_connection((host, port), timeout,
  File "/usr/local/lib/python3.8/socket.py", line 808, in create_connection
    raise err
  File "/usr/local/lib/python3.8/socket.py", line 796, in create_connection
    sock.connect(sa)
OSError: [Errno 99] Cannot assign requested address
[2023-10-21T16:46:29.292+0800] {standard_task_runner.py:104} ERROR - Failed to execute job 199 for task check_stock_price (xcom_pull() got an unexpected keyword argument 'task_id'; 254)
[2023-10-21T16:46:29.329+0800] {local_task_job_runner.py:228} INFO - Task exited with return code 1
[2023-10-21T16:46:29.346+0800] {taskinstance.py:2778} INFO - 0 downstream tasks scheduled from follow-on schedule check
