[2023-10-26T18:08:53.917+0800] {taskinstance.py:1157} INFO - Dependencies all met for dep_context=non-requeueable deps ti=<TaskInstance: dag_with_minio_v1.sensor_minio_s3 manual__2023-10-26T10:08:52.042039+00:00 [queued]>
[2023-10-26T18:08:53.929+0800] {taskinstance.py:1157} INFO - Dependencies all met for dep_context=requeueable deps ti=<TaskInstance: dag_with_minio_v1.sensor_minio_s3 manual__2023-10-26T10:08:52.042039+00:00 [queued]>
[2023-10-26T18:08:53.929+0800] {taskinstance.py:1359} INFO - Starting attempt 1 of 2
[2023-10-26T18:08:53.942+0800] {taskinstance.py:1380} INFO - Executing <Task(S3KeySensor): sensor_minio_s3> on 2023-10-26 10:08:52.042039+00:00
[2023-10-26T18:08:53.948+0800] {standard_task_runner.py:57} INFO - Started process 1334 to run task
[2023-10-26T18:08:53.951+0800] {standard_task_runner.py:84} INFO - Running: ['***', 'tasks', 'run', 'dag_with_minio_v1', 'sensor_minio_s3', 'manual__2023-10-26T10:08:52.042039+00:00', '--job-id', '638', '--raw', '--subdir', 'DAGS_FOLDER/dag_with_minio.py', '--cfg-path', '/tmp/tmp0_k265td']
[2023-10-26T18:08:53.954+0800] {standard_task_runner.py:85} INFO - Job 638: Subtask sensor_minio_s3
[2023-10-26T18:08:53.995+0800] {task_command.py:415} INFO - Running <TaskInstance: dag_with_minio_v1.sensor_minio_s3 manual__2023-10-26T10:08:52.042039+00:00 [running]> on host 26a4c5bc8d30
[2023-10-26T18:08:54.042+0800] {taskinstance.py:1660} INFO - Exporting env vars: AIRFLOW_CTX_DAG_EMAIL='joshua881117@gmail.com' AIRFLOW_CTX_DAG_OWNER='Joshua Lin' AIRFLOW_CTX_DAG_ID='dag_with_minio_v1' AIRFLOW_CTX_TASK_ID='sensor_minio_s3' AIRFLOW_CTX_EXECUTION_DATE='2023-10-26T10:08:52.042039+00:00' AIRFLOW_CTX_TRY_NUMBER='1' AIRFLOW_CTX_DAG_RUN_ID='manual__2023-10-26T10:08:52.042039+00:00'
[2023-10-26T18:08:54.043+0800] {s3.py:106} INFO - Poking for key : s3://***/result.csv
[2023-10-26T18:08:54.047+0800] {base.py:73} INFO - Using connection ID 'minio_conn' for task execution.
[2023-10-26T18:08:54.047+0800] {connection_wrapper.py:340} INFO - AWS Connection (conn_id='minio_conn', conn_type='aws') credentials retrieved from login and password.
[2023-10-26T18:08:55.496+0800] {taskinstance.py:1935} ERROR - Task failed with exception
Traceback (most recent call last):
  File "/home/airflow/.local/lib/python3.8/site-packages/airflow/providers/amazon/aws/sensors/s3.py", line 144, in execute
    super().execute(context)
  File "/home/airflow/.local/lib/python3.8/site-packages/airflow/sensors/base.py", line 257, in execute
    raise e
  File "/home/airflow/.local/lib/python3.8/site-packages/airflow/sensors/base.py", line 239, in execute
    poke_return = self.poke(context)
  File "/home/airflow/.local/lib/python3.8/site-packages/airflow/providers/amazon/aws/sensors/s3.py", line 137, in poke
    return self._check_key(self.bucket_key)
  File "/home/airflow/.local/lib/python3.8/site-packages/airflow/providers/amazon/aws/sensors/s3.py", line 125, in _check_key
    obj = self.hook.head_object(key, bucket_name)
  File "/home/airflow/.local/lib/python3.8/site-packages/airflow/providers/amazon/aws/hooks/s3.py", line 136, in wrapper
    return func(*bound_args.args, **bound_args.kwargs)
  File "/home/airflow/.local/lib/python3.8/site-packages/airflow/providers/amazon/aws/hooks/s3.py", line 90, in wrapper
    return func(*bound_args.args, **bound_args.kwargs)
  File "/home/airflow/.local/lib/python3.8/site-packages/airflow/providers/amazon/aws/hooks/s3.py", line 884, in head_object
    raise e
  File "/home/airflow/.local/lib/python3.8/site-packages/airflow/providers/amazon/aws/hooks/s3.py", line 879, in head_object
    return self.get_conn().head_object(Bucket=bucket_name, Key=key)
  File "/home/airflow/.local/lib/python3.8/site-packages/botocore/client.py", line 535, in _api_call
    return self._make_api_call(operation_name, kwargs)
  File "/home/airflow/.local/lib/python3.8/site-packages/botocore/client.py", line 980, in _make_api_call
    raise error_class(parsed_response, operation_name)
botocore.exceptions.ClientError: An error occurred (403) when calling the HeadObject operation: Forbidden
[2023-10-26T18:08:55.527+0800] {taskinstance.py:1398} INFO - Marking task as UP_FOR_RETRY. dag_id=dag_with_minio_v1, task_id=sensor_minio_s3, execution_date=20231026T100852, start_date=20231026T100853, end_date=20231026T100855
[2023-10-26T18:08:55.548+0800] {standard_task_runner.py:104} ERROR - Failed to execute job 638 for task sensor_minio_s3 (An error occurred (403) when calling the HeadObject operation: Forbidden; 1334)
[2023-10-26T18:08:55.617+0800] {local_task_job_runner.py:228} INFO - Task exited with return code 1
[2023-10-26T18:08:55.661+0800] {taskinstance.py:2776} INFO - 0 downstream tasks scheduled from follow-on schedule check
