[2023-10-25T20:38:27.633+0800] {taskinstance.py:1159} INFO - Dependencies all met for dep_context=non-requeueable deps ti=<TaskInstance: stock_data_crawler.upload_to_db scheduled__2023-10-24T10:00:00+00:00 [queued]>
[2023-10-25T20:38:27.649+0800] {taskinstance.py:1159} INFO - Dependencies all met for dep_context=requeueable deps ti=<TaskInstance: stock_data_crawler.upload_to_db scheduled__2023-10-24T10:00:00+00:00 [queued]>
[2023-10-25T20:38:27.650+0800] {taskinstance.py:1361} INFO - Starting attempt 4 of 5
[2023-10-25T20:38:27.662+0800] {taskinstance.py:1382} INFO - Executing <Task(PythonOperator): upload_to_db> on 2023-10-24 10:00:00+00:00
[2023-10-25T20:38:27.676+0800] {standard_task_runner.py:57} INFO - Started process 4081 to run task
[2023-10-25T20:38:27.681+0800] {standard_task_runner.py:84} INFO - Running: ['***', 'tasks', 'run', 'stock_data_crawler', 'upload_to_db', 'scheduled__2023-10-24T10:00:00+00:00', '--job-id', '456', '--raw', '--subdir', 'DAGS_FOLDER/stock_data_crawler.py', '--cfg-path', '/tmp/tmpm65_yl03']
[2023-10-25T20:38:27.688+0800] {standard_task_runner.py:85} INFO - Job 456: Subtask upload_to_db
[2023-10-25T20:38:27.726+0800] {task_command.py:416} INFO - Running <TaskInstance: stock_data_crawler.upload_to_db scheduled__2023-10-24T10:00:00+00:00 [running]> on host bb5c9ebbc514
[2023-10-25T20:38:27.770+0800] {taskinstance.py:1662} INFO - Exporting env vars: AIRFLOW_CTX_DAG_EMAIL='joshua881117@gmail.com' AIRFLOW_CTX_DAG_OWNER='Joshua Lin' AIRFLOW_CTX_DAG_ID='stock_data_crawler' AIRFLOW_CTX_TASK_ID='upload_to_db' AIRFLOW_CTX_EXECUTION_DATE='2023-10-24T10:00:00+00:00' AIRFLOW_CTX_TRY_NUMBER='4' AIRFLOW_CTX_DAG_RUN_ID='scheduled__2023-10-24T10:00:00+00:00'
[2023-10-25T20:38:27.771+0800] {logging_mixin.py:151} INFO - /opt/***/data/stock_data_<built-in method date of datetime.datetime object at 0xffff83a85930>.csv
[2023-10-25T20:38:27.775+0800] {taskinstance.py:1937} ERROR - Task failed with exception
Traceback (most recent call last):
  File "/home/airflow/.local/lib/python3.8/site-packages/airflow/operators/python.py", line 192, in execute
    return_value = self.execute_callable()
  File "/home/airflow/.local/lib/python3.8/site-packages/airflow/operators/python.py", line 209, in execute_callable
    return self.python_callable(*self.op_args, **self.op_kwargs)
  File "/opt/airflow/dags/stock_data_crawler.py", line 53, in upload_data
    df = pd.read_csv(file_path)
  File "/home/airflow/.local/lib/python3.8/site-packages/pandas/io/parsers/readers.py", line 912, in read_csv
    return _read(filepath_or_buffer, kwds)
  File "/home/airflow/.local/lib/python3.8/site-packages/pandas/io/parsers/readers.py", line 577, in _read
    parser = TextFileReader(filepath_or_buffer, **kwds)
  File "/home/airflow/.local/lib/python3.8/site-packages/pandas/io/parsers/readers.py", line 1407, in __init__
    self._engine = self._make_engine(f, self.engine)
  File "/home/airflow/.local/lib/python3.8/site-packages/pandas/io/parsers/readers.py", line 1661, in _make_engine
    self.handles = get_handle(
  File "/home/airflow/.local/lib/python3.8/site-packages/pandas/io/common.py", line 859, in get_handle
    handle = open(
FileNotFoundError: [Errno 2] No such file or directory: '/opt/airflow/data/stock_data_<built-in method date of datetime.datetime object at 0xffff83a85930>.csv'
[2023-10-25T20:38:27.783+0800] {taskinstance.py:1400} INFO - Marking task as UP_FOR_RETRY. dag_id=stock_data_crawler, task_id=upload_to_db, execution_date=20231024T100000, start_date=20231025T123827, end_date=20231025T123827
[2023-10-25T20:38:27.792+0800] {standard_task_runner.py:104} ERROR - Failed to execute job 456 for task upload_to_db ([Errno 2] No such file or directory: '/opt/airflow/data/stock_data_<built-in method date of datetime.datetime object at 0xffff83a85930>.csv'; 4081)
[2023-10-25T20:38:27.812+0800] {local_task_job_runner.py:228} INFO - Task exited with return code 1
[2023-10-25T20:38:27.822+0800] {taskinstance.py:2778} INFO - 0 downstream tasks scheduled from follow-on schedule check
