[2023-10-23T20:49:44.445+0800] {taskinstance.py:1159} INFO - Dependencies all met for dep_context=non-requeueable deps ti=<TaskInstance: stock_data_crawler.make_weekend_choice scheduled__2023-10-22T10:00:00+00:00 [queued]>
[2023-10-23T20:49:44.452+0800] {taskinstance.py:1159} INFO - Dependencies all met for dep_context=requeueable deps ti=<TaskInstance: stock_data_crawler.make_weekend_choice scheduled__2023-10-22T10:00:00+00:00 [queued]>
[2023-10-23T20:49:44.453+0800] {taskinstance.py:1361} INFO - Starting attempt 1 of 2
[2023-10-23T20:49:44.471+0800] {taskinstance.py:1382} INFO - Executing <Task(BranchDayOfWeekOperator): make_weekend_choice> on 2023-10-22 10:00:00+00:00
[2023-10-23T20:49:44.480+0800] {standard_task_runner.py:57} INFO - Started process 1033 to run task
[2023-10-23T20:49:44.491+0800] {standard_task_runner.py:84} INFO - Running: ['***', 'tasks', 'run', 'stock_data_crawler', 'make_weekend_choice', 'scheduled__2023-10-22T10:00:00+00:00', '--job-id', '91', '--raw', '--subdir', 'DAGS_FOLDER/stock_data_crawler.py', '--cfg-path', '/tmp/tmpupbsz_7u']
[2023-10-23T20:49:44.498+0800] {standard_task_runner.py:85} INFO - Job 91: Subtask make_weekend_choice
[2023-10-23T20:49:44.575+0800] {task_command.py:416} INFO - Running <TaskInstance: stock_data_crawler.make_weekend_choice scheduled__2023-10-22T10:00:00+00:00 [running]> on host 13b1047ff76f
[2023-10-23T20:49:48.849+0800] {standard_task_runner.py:104} ERROR - Failed to execute job 91 for task make_weekend_choice ((pymysql.err.OperationalError) (2013, 'Lost connection to MySQL server during query')
[SQL: SELECT task_instance.try_number AS task_instance_try_number, task_instance.task_id AS task_instance_task_id, task_instance.dag_id AS task_instance_dag_id, task_instance.run_id AS task_instance_run_id, task_instance.map_index AS task_instance_map_index, task_instance.start_date AS task_instance_start_date, task_instance.end_date AS task_instance_end_date, task_instance.duration AS task_instance_duration, task_instance.state AS task_instance_state, task_instance.max_tries AS task_instance_max_tries, task_instance.hostname AS task_instance_hostname, task_instance.unixname AS task_instance_unixname, task_instance.job_id AS task_instance_job_id, task_instance.pool AS task_instance_pool, task_instance.pool_slots AS task_instance_pool_slots, task_instance.queue AS task_instance_queue, task_instance.priority_weight AS task_instance_priority_weight, task_instance.operator AS task_instance_operator, task_instance.custom_operator_name AS task_instance_custom_operator_name, task_instance.queued_dttm AS task_instance_queued_dttm, task_instance.queued_by_job_id AS task_instance_queued_by_job_id, task_instance.pid AS task_instance_pid, task_instance.executor_config AS task_instance_executor_config, task_instance.updated_at AS task_instance_updated_at, task_instance.external_executor_id AS task_instance_external_executor_id, task_instance.trigger_id AS task_instance_trigger_id, task_instance.trigger_timeout AS task_instance_trigger_timeout, task_instance.next_method AS task_instance_next_method, task_instance.next_kwargs AS task_instance_next_kwargs, dag_run_1.state AS dag_run_1_state, dag_run_1.id AS dag_run_1_id, dag_run_1.dag_id AS dag_run_1_dag_id, dag_run_1.queued_at AS dag_run_1_queued_at, dag_run_1.execution_date AS dag_run_1_execution_date, dag_run_1.start_date AS dag_run_1_start_date, dag_run_1.end_date AS dag_run_1_end_date, dag_run_1.run_id AS dag_run_1_run_id, dag_run_1.creating_job_id AS dag_run_1_creating_job_id, dag_run_1.external_trigger AS dag_run_1_external_trigger, dag_run_1.run_type AS dag_run_1_run_type, dag_run_1.conf AS dag_run_1_conf, dag_run_1.data_interval_start AS dag_run_1_data_interval_start, dag_run_1.data_interval_end AS dag_run_1_data_interval_end, dag_run_1.last_scheduling_decision AS dag_run_1_last_scheduling_decision, dag_run_1.dag_hash AS dag_run_1_dag_hash, dag_run_1.log_template_id AS dag_run_1_log_template_id, dag_run_1.updated_at AS dag_run_1_updated_at 
FROM task_instance INNER JOIN dag_run AS dag_run_1 ON dag_run_1.dag_id = task_instance.dag_id AND dag_run_1.run_id = task_instance.run_id 
WHERE task_instance.dag_id = %(pk_1)s AND task_instance.task_id = %(pk_2)s AND task_instance.run_id = %(pk_3)s AND task_instance.map_index = %(pk_4)s]
[parameters: {'pk_1': 'stock_data_crawler', 'pk_2': 'make_weekend_choice', 'pk_3': 'scheduled__2023-10-22T10:00:00+00:00', 'pk_4': -1}]
(Background on this error at: https://sqlalche.me/e/14/e3q8); 1033)
[2023-10-23T20:49:49.060+0800] {local_task_job_runner.py:228} INFO - Task exited with return code 1
[2023-10-23T20:49:49.216+0800] {taskinstance.py:2784} INFO - Skipping mini scheduling run due to exception: None
Traceback (most recent call last):
  File "/home/airflow/.local/lib/python3.8/site-packages/pymysql/connections.py", line 644, in connect
    sock = socket.create_connection(
  File "/usr/local/lib/python3.8/socket.py", line 808, in create_connection
    raise err
  File "/usr/local/lib/python3.8/socket.py", line 796, in create_connection
    sock.connect(sa)
ConnectionRefusedError: [Errno 111] Connection refused

During handling of the above exception, another exception occurred:

Traceback (most recent call last):
  File "/home/airflow/.local/lib/python3.8/site-packages/sqlalchemy/engine/base.py", line 3371, in _wrap_pool_connect
    return fn()
  File "/home/airflow/.local/lib/python3.8/site-packages/sqlalchemy/pool/base.py", line 327, in connect
    return _ConnectionFairy._checkout(self)
  File "/home/airflow/.local/lib/python3.8/site-packages/sqlalchemy/pool/base.py", line 894, in _checkout
    fairy = _ConnectionRecord.checkout(pool)
  File "/home/airflow/.local/lib/python3.8/site-packages/sqlalchemy/pool/base.py", line 493, in checkout
    rec = pool._do_get()
  File "/home/airflow/.local/lib/python3.8/site-packages/sqlalchemy/pool/impl.py", line 256, in _do_get
    return self._create_connection()
  File "/home/airflow/.local/lib/python3.8/site-packages/sqlalchemy/pool/base.py", line 273, in _create_connection
    return _ConnectionRecord(self)
  File "/home/airflow/.local/lib/python3.8/site-packages/sqlalchemy/pool/base.py", line 388, in __init__
    self.__connect()
  File "/home/airflow/.local/lib/python3.8/site-packages/sqlalchemy/pool/base.py", line 691, in __connect
    pool.logger.debug("Error on connect(): %s", e)
  File "/home/airflow/.local/lib/python3.8/site-packages/sqlalchemy/util/langhelpers.py", line 70, in __exit__
    compat.raise_(
  File "/home/airflow/.local/lib/python3.8/site-packages/sqlalchemy/util/compat.py", line 211, in raise_
    raise exception
  File "/home/airflow/.local/lib/python3.8/site-packages/sqlalchemy/pool/base.py", line 686, in __connect
    self.dbapi_connection = connection = pool._invoke_creator(self)
  File "/home/airflow/.local/lib/python3.8/site-packages/sqlalchemy/engine/create.py", line 574, in connect
    return dialect.connect(*cargs, **cparams)
  File "/home/airflow/.local/lib/python3.8/site-packages/sqlalchemy/engine/default.py", line 598, in connect
    return self.dbapi.connect(*cargs, **cparams)
  File "/home/airflow/.local/lib/python3.8/site-packages/pymysql/connections.py", line 358, in __init__
    self.connect()
  File "/home/airflow/.local/lib/python3.8/site-packages/pymysql/connections.py", line 711, in connect
    raise exc
pymysql.err.OperationalError: (2003, "Can't connect to MySQL server on 'mysql' ([Errno 111] Connection refused)")

The above exception was the direct cause of the following exception:

Traceback (most recent call last):
  File "/home/airflow/.local/lib/python3.8/site-packages/airflow/models/taskinstance.py", line 2733, in schedule_downstream_tasks
    dag_run = with_row_locks(
  File "/home/airflow/.local/lib/python3.8/site-packages/sqlalchemy/orm/query.py", line 2870, in one
    return self._iter().one()
  File "/home/airflow/.local/lib/python3.8/site-packages/sqlalchemy/orm/query.py", line 2916, in _iter
    result = self.session.execute(
  File "/home/airflow/.local/lib/python3.8/site-packages/sqlalchemy/orm/session.py", line 1716, in execute
    conn = self._connection_for_bind(bind)
  File "/home/airflow/.local/lib/python3.8/site-packages/sqlalchemy/orm/session.py", line 1555, in _connection_for_bind
    return self._transaction._connection_for_bind(
  File "/home/airflow/.local/lib/python3.8/site-packages/sqlalchemy/orm/session.py", line 750, in _connection_for_bind
    conn = bind.connect()
  File "/home/airflow/.local/lib/python3.8/site-packages/sqlalchemy/future/engine.py", line 406, in connect
    return super(Engine, self).connect()
  File "/home/airflow/.local/lib/python3.8/site-packages/sqlalchemy/engine/base.py", line 3325, in connect
    return self._connection_cls(self, close_with_result=close_with_result)
  File "/home/airflow/.local/lib/python3.8/site-packages/sqlalchemy/engine/base.py", line 96, in __init__
    else engine.raw_connection()
  File "/home/airflow/.local/lib/python3.8/site-packages/sqlalchemy/engine/base.py", line 3404, in raw_connection
    return self._wrap_pool_connect(self.pool.connect, _connection)
  File "/home/airflow/.local/lib/python3.8/site-packages/sqlalchemy/engine/base.py", line 3374, in _wrap_pool_connect
    Connection._handle_dbapi_exception_noconnection(
  File "/home/airflow/.local/lib/python3.8/site-packages/sqlalchemy/engine/base.py", line 2208, in _handle_dbapi_exception_noconnection
    util.raise_(
  File "/home/airflow/.local/lib/python3.8/site-packages/sqlalchemy/util/compat.py", line 211, in raise_
    raise exception
  File "/home/airflow/.local/lib/python3.8/site-packages/sqlalchemy/engine/base.py", line 3371, in _wrap_pool_connect
    return fn()
  File "/home/airflow/.local/lib/python3.8/site-packages/sqlalchemy/pool/base.py", line 327, in connect
    return _ConnectionFairy._checkout(self)
  File "/home/airflow/.local/lib/python3.8/site-packages/sqlalchemy/pool/base.py", line 894, in _checkout
    fairy = _ConnectionRecord.checkout(pool)
  File "/home/airflow/.local/lib/python3.8/site-packages/sqlalchemy/pool/base.py", line 493, in checkout
    rec = pool._do_get()
  File "/home/airflow/.local/lib/python3.8/site-packages/sqlalchemy/pool/impl.py", line 256, in _do_get
    return self._create_connection()
  File "/home/airflow/.local/lib/python3.8/site-packages/sqlalchemy/pool/base.py", line 273, in _create_connection
    return _ConnectionRecord(self)
  File "/home/airflow/.local/lib/python3.8/site-packages/sqlalchemy/pool/base.py", line 388, in __init__
    self.__connect()
  File "/home/airflow/.local/lib/python3.8/site-packages/sqlalchemy/pool/base.py", line 691, in __connect
    pool.logger.debug("Error on connect(): %s", e)
  File "/home/airflow/.local/lib/python3.8/site-packages/sqlalchemy/util/langhelpers.py", line 70, in __exit__
    compat.raise_(
  File "/home/airflow/.local/lib/python3.8/site-packages/sqlalchemy/util/compat.py", line 211, in raise_
    raise exception
  File "/home/airflow/.local/lib/python3.8/site-packages/sqlalchemy/pool/base.py", line 686, in __connect
    self.dbapi_connection = connection = pool._invoke_creator(self)
  File "/home/airflow/.local/lib/python3.8/site-packages/sqlalchemy/engine/create.py", line 574, in connect
    return dialect.connect(*cargs, **cparams)
  File "/home/airflow/.local/lib/python3.8/site-packages/sqlalchemy/engine/default.py", line 598, in connect
    return self.dbapi.connect(*cargs, **cparams)
  File "/home/airflow/.local/lib/python3.8/site-packages/pymysql/connections.py", line 358, in __init__
    self.connect()
  File "/home/airflow/.local/lib/python3.8/site-packages/pymysql/connections.py", line 711, in connect
    raise exc
sqlalchemy.exc.OperationalError: (pymysql.err.OperationalError) (2003, "Can't connect to MySQL server on 'mysql' ([Errno 111] Connection refused)")
(Background on this error at: https://sqlalche.me/e/14/e3q8)
